<?xml version="1.0"?>
<robot name="beaker">
  <material name="blue">
    <color rgba="0 0 0.8 1"/>
  </material>

  <material name="pink">
    <color rgba="1 0.5 0.5 1"/>
  </material>
  
  <material name="gray">
    <color rgba="0.7 0.7 0.7 1"/>
  </material>

   <material name="red">
    <color rgba="0.8 0 0 1"/>
  </material>

   <material name="green">
    <color rgba="0 0.8 0 1"/>
  </material>

   <material name="white">
    <color rgba="1 1 1 1"/>
  </material>

  <!-- .......................................................................................... -->
  <!-- Main Body -->
  <link name="body">
    <visual>
      <geometry>
        <box size="0.1016 0.0254 0.6604"/>
      </geometry>
      <origin xyz="0 0 0.3302" />
      <material name="gray"/>
    </visual>

    <!-- axle -->
    <visual>
      <geometry>
        <cylinder length="0.17" radius=".01"/>
      </geometry>
      <origin rpy="0 1.5707963 0" xyz="0 0 0.01905"/>
      <material name="gray"/>
    </visual>

    <collision>
      <geometry>
        <box size="0.1016 0.0254 0.6604"/>
      </geometry>
      <origin xyz="0 0 0.4" />
    </collision>

    <inertial>
      <origin rpy="0 0 0" xyz="0 0 0.2159"/>
      <mass value="1.767" />

      <!-- https://en.wikipedia.org/wiki/List_of_moments_of_inertia -->
      <!-- see "slender rod along y axis" -->
      <inertia ixx="0.12212" ixy="0.0" ixz="0.0" iyy="0.0" iyz="0.0" izz="0.12212"/>
    </inertial>
  </link>

  <!-- .......................................................................................... -->
  <link name="face">
    <visual>
      <geometry>
        <box size="0.05 0.01 0.05"/>
      </geometry>
      <origin xyz="0 0.010 0.5" />
      <material name="pink"/>
    </visual>

    <!-- Just visual aid. Has no mass -->
    <inertial>
      <mass value="0" />
      <inertia ixx="0" ixy="0.0" ixz="0.0" iyy="0" iyz="0.0" izz="0"/>
    </inertial>
  </link>
  <joint name="face_joint" type="fixed">
    <parent link="body"/>
    <child link="face"/>
  </joint>

  <!-- .......................................................................................... -->
  <!-- right Wheel -->
  <link name="right_wheel">

    <!-- main wheel visual -->
    <visual>
      <geometry>
        <cylinder length="0.0254" radius=".042"/>
      </geometry>
      <origin rpy="0 1.5707963 0" xyz="0 0 0"/>
      <material name="green"/>
    </visual>

    <collision>
      <geometry>
        <cylinder length="0.0254" radius=".042"/>
      </geometry>
      <origin rpy="0 1.5707963 0" xyz="0 0 0"/>
      <contact_coefficients mu="0.01" />
    </collision>

    <inertial>
      <origin rpy="0 0 0" xyz="0 0 0.2159"/>
      <mass value="0.09" />

      <!-- https://en.wikipedia.org/wiki/List_of_moments_of_inertia -->
      <!-- see "slender rod along y axis" -->
      <!-- wheel radius is .084m -->
      <inertia ixx="0.00004453" ixy="0.0" ixz="0.0" iyy="0.00004453" iyz="0.0" izz="0.00007938"/>
    </inertial>
  </link>

  <!-- right Wheel Joint To Body -->
  <joint name="base_to_right_wheel" type="continuous">
    <parent link="body"/>
    <child link="right_wheel"/>
    <origin xyz="0.09398 0.0 0.01905" />
    <axis xyz="1 0 0"/>
  </joint>

  <!-- helps to see the wheel rotation -->
  <link name="right_wheel_stripe">
    <visual>
      <geometry>
        <box size="0.01 0.01 0.08"/>
      </geometry>
      <origin xyz="0.01 0 0" />
      <material name="blue"/>
    </visual> 

    <!-- Just visual aid. Has no mass -->
    <inertial>
      <mass value="0" />
      <inertia ixx="0" ixy="0.0" ixz="0.0" iyy="0" iyz="0.0" izz="0"/>
    </inertial>
  </link>
  <joint name="right_wheel_to_stripe" type="fixed">
    <parent link="right_wheel"/>
    <child link="right_wheel_stripe"/>
  </joint>

  <!-- .......................................................................................... -->
  <!-- left Wheel -->
  <link name="left_wheel">
    <visual>
      <geometry>
        <cylinder length="0.0254" radius=".042"/>
      </geometry>
      <origin rpy="0 1.5707963 0" xyz="0 0 0"/>
      <material name="red"/>
    </visual>

    <collision>
      <geometry>
        <cylinder length="0.0254" radius=".042"/>
      </geometry>
      <origin rpy="0 1.5707963 0" xyz="0 0 0"/>
      <contact_coefficients mu="0.01" />
    </collision>

    <inertial>
      <origin rpy="0 0 0" xyz="0 0 0.2159"/>
      <mass value="0.09" />

      <!-- https://en.wikipedia.org/wiki/List_of_moments_of_inertia -->
      <!-- see "slender rod along y axis" -->
      <!-- wheel radius is .084m -->
      <inertia ixx="0.00004453" ixy="0.0" ixz="0.0" iyy="0.00004453" iyz="0.0" izz="0.00007938"/>
    </inertial>
  </link>

  <!-- left Wheel Joint to Body -->
  <joint name="base_to_left_wheel" type="continuous">
    <parent link="body"/>
    <child link="left_wheel"/>
    <origin xyz="-0.09398 0.0 0.01905" />
    <axis xyz="1 0 0"/>
  </joint>

  <!-- .......................................................................................... -->
  <!-- helps to see the wheel rotation -->
  <link name="left_wheel_stripe">
    <visual>
      <geometry>
        <box size="0.01 0.01 0.08"/>
      </geometry>
      <origin xyz="-0.01 0 0" />
      <material name="blue"/>
    </visual> 

    <!-- Just visual aid. Has no mass -->
    <inertial>
      <mass value="0" />
      <inertia ixx="0" ixy="0.0" ixz="0.0" iyy="0" iyz="0.0" izz="0"/>
    </inertial>
  </link>
  <joint name="left_wheel_to_stripe" type="fixed">
    <parent link="left_wheel"/>
    <child link="left_wheel_stripe"/>
  </joint>

  <!-- .......................................................................................... -->
  <!-- training wheels front strut  -->
  <link name="front_training_wheel_strut">
    <visual>
      <geometry>
        <box size="0.1016 0.01 0.508"/>
      </geometry>
      <origin xyz="0 0.22 0.15" rpy="45 0 0"/>
      <material name="white"/>
    </visual>
    <collision>
      <geometry>
         <box size="0.1016 0.01 0.508"/>
      </geometry>
      <origin xyz="0 0.22 0.15" rpy="45 0 0"/>
      <contact_coefficients mu="0.0" />
    </collision> 

    <inertial>
      <origin rpy="0 0 0" xyz="0 0 0"/>
      <mass value="0.000001" />
      <inertia ixx="0.000001" ixy="0.0" ixz="0.0" iyy="0.00000001" iyz="0.0" izz="0.00000001"/>
    </inertial>
  </link>
  <joint name="front_strut_joint" type="fixed">
    <parent link="body"/>
    <child link="front_training_wheel_strut"/>
  </joint>

  <!-- .......................................................................................... -->
  <!-- left Wheel front strut -->
  <link name="left_wheel_front">
    <visual>
      <geometry>
        <cylinder length="0.0254" radius=".042"/>
      </geometry>
      <origin rpy="0 1.5707963 0" xyz="0 0 0"/>
      <material name="red"/>
    </visual>

    <collision>
      <geometry>
        <cylinder length="0.0254" radius=".042"/>
      </geometry>
      <origin rpy="0 1.5707963 0" xyz="0 0 0"/>
      <contact_coefficients mu="0.001" />
    </collision>

    <inertial>
      <origin rpy="0 0 0" xyz="0 0 0.2159"/>
      <mass value="0.001" />

      <!-- https://en.wikipedia.org/wiki/List_of_moments_of_inertia -->
      <!-- see "slender rod along y axis" -->
      <!-- wheel radius is .084m -->
      <inertia ixx="0.00004453" ixy="0.0" ixz="0.0" iyy="0.00004453" iyz="0.0" izz="0.00007938"/>
    </inertial>
  </link>

  <!-- left Wheel traiing Joint to front strut -->
  <joint name="front_strut_to_front_left_wheel" type="continuous">
    <parent link="front_training_wheel_strut"/>
    <child link="left_wheel_front"/>
    <origin xyz="-0.09398 0.42 0.01905" />
    <axis xyz="1 0 0"/>
  </joint>

  <!-- .......................................................................................... -->
  <!-- right Wheel front strut -->
  <link name="right_wheel_front">
    <visual>
      <geometry>
        <cylinder length="0.0254" radius=".042"/>
      </geometry>
      <origin rpy="0 1.5707963 0" xyz="0 0 0"/>
      <material name="green"/>
    </visual>

    <collision>
      <geometry>
        <cylinder length="0.0254" radius=".042"/>
      </geometry>
      <origin rpy="0 1.5707963 0" xyz="0 0 0"/>
      <contact_coefficients mu="0.001" />
    </collision>

    <inertial>
      <origin rpy="0 0 0" xyz="0 0 0.2159"/>
      <mass value="0.001" />

      <!-- https://en.wikipedia.org/wiki/List_of_moments_of_inertia -->
      <!-- see "slender rod along y axis" -->
      <!-- wheel radius is .084m -->
      <inertia ixx="0.00004453" ixy="0.0" ixz="0.0" iyy="0.00004453" iyz="0.0" izz="0.00007938"/>
    </inertial>
  </link>

  <!-- left Wheel Joint to Body -->
  <joint name="front_strut_to_front_right_wheel" type="continuous">
    <parent link="front_training_wheel_strut"/>
    <child link="right_wheel_front"/>
    <origin xyz="0.09398 0.42 0.01905" />
    <axis xyz="1 0 0"/>
  </joint>

    <!-- .......................................................................................... -->
  <!-- helps to see the wheel rotation -->
  <link name="right_wheel_front_stripe">
    <visual>
      <geometry>
        <box size="0.01 0.01 0.08"/>
      </geometry>
      <origin xyz="0.01 0 0" />
      <material name="blue"/>
    </visual> 

    <!-- Just visual aid. Has no mass -->
    <inertial>
      <mass value="0" />
      <inertia ixx="0" ixy="0.0" ixz="0.0" iyy="0" iyz="0.0" izz="0"/>
    </inertial>
  </link>
  <joint name="right_wheel_front_to_stripe" type="fixed">
    <parent link="right_wheel_front"/>
    <child link="right_wheel_front_stripe"/>
  </joint>

  <!-- .......................................................................................... -->
  <!-- traing wheel rear strut -->
   <link name="rear_training_wheel_strut">
    <visual>
      <geometry>
        <box size="0.1016 0.01 0.508"/>
      </geometry>
      <origin xyz="0 -0.22 0.15" rpy="-45 0 0"/>
      <material name="white"/>
    </visual>
    <collision>
      <geometry>
         <box size="0.1016 0.01 0.508"/>
      </geometry>
      <origin xyz="0 -0.22 0.15" rpy="-45 0 0"/>
      <contact_coefficients mu="0.0" />
    </collision> 
    <inertial>
      <origin rpy="0 0 0" xyz="0 0 0"/>
      <mass value="0.0001" />
      <inertia ixx="0.0001" ixy="0.0" ixz="0.00000001" iyy="0.0" iyz="0.0" izz="0.00000001"/>
    </inertial>
  </link>
  <joint name="rear_strut_joint" type="fixed">
    <parent link="body"/>
    <child link="rear_training_wheel_strut"/>
  </joint>

  <!-- .......................................................................................... -->
  <!-- right Wheel rear strut -->
  <link name="right_wheel_rear">
    <visual>
      <geometry>
        <cylinder length="0.0254" radius=".042"/>
      </geometry>
      <origin rpy="0 1.5707963 0" xyz="0 0 0"/>
      <material name="green"/>
    </visual>

    <collision>
      <geometry>
        <cylinder length="0.0254" radius=".042"/>
      </geometry>
      <origin rpy="0 1.5707963 0" xyz="0 0 0"/>
      <contact_coefficients mu="0.001" />
    </collision>

    <inertial>
      <origin rpy="0 0 0" xyz="0 0 0.2159"/>
      <mass value="0.001" />

      <!-- https://en.wikipedia.org/wiki/List_of_moments_of_inertia -->
      <!-- see "slender rod along y axis" -->
      <!-- wheel radius is .084m -->
      <inertia ixx="0.00004453" ixy="0.0" ixz="0.0" iyy="0.00004453" iyz="0.0" izz="0.00007938"/>
    </inertial>
  </link>

  <!-- left Wheel Joint to Body -->
  <joint name="rear_strut_to_rear_right_wheel" type="continuous">
    <parent link="rear_training_wheel_strut"/>
    <child link="right_wheel_rear"/>
    <origin xyz="0.09398 -0.42 0.01905" />
    <axis xyz="1 0 0"/>
  </joint>

  <!-- .......................................................................................... -->
  <!-- helps to see the wheel rotation -->
  <link name="right_wheel_rear_stripe">
    <visual>
      <geometry>
        <box size="0.01 0.01 0.08"/>
      </geometry>
      <origin xyz="0.01 0 0" />
      <material name="blue"/>
    </visual> 

    <!-- Just visual aid. Has no mass -->
    <inertial>
      <mass value="0" />
      <inertia ixx="0" ixy="0.0" ixz="0.0" iyy="0" iyz="0.0" izz="0"/>
    </inertial>
  </link>
  <joint name="right_wheel_rear_to_stripe" type="fixed">
    <parent link="right_wheel_rear"/>
    <child link="right_wheel_rear_stripe"/>
  </joint>

  <!-- .......................................................................................... -->
  <!-- left Wheel rear strut -->
  <link name="left_wheel_rear">
    <visual>
      <geometry>
        <cylinder length="0.0254" radius=".042"/>
      </geometry>
      <origin rpy="0 1.5707963 0" xyz="0 0 0"/>
      <material name="red"/>
    </visual>

    <collision>
      <geometry>
        <cylinder length="0.0254" radius=".042"/>
      </geometry>
      <origin rpy="0 1.5707963 0" xyz="0 0 0"/>
      <contact_coefficients mu="0.001" />
    </collision>

    <inertial>
      <origin rpy="0 0 0" xyz="0 0 0.2159"/>
      <mass value="0.001" />

      <!-- https://en.wikipedia.org/wiki/List_of_moments_of_inertia -->
      <!-- see "slender rod along y axis" -->
      <!-- wheel radius is .084m -->
      <inertia ixx="0.00004453" ixy="0.0" ixz="0.0" iyy="0.00004453" iyz="0.0" izz="0.00007938"/>
    </inertial>
  </link>

  <!-- left Wheel Joint to Body -->
  <joint name="rear_strut_to_rear_left_wheel" type="continuous">
    <parent link="rear_training_wheel_strut"/>
    <child link="left_wheel_rear"/>
    <origin xyz="-0.09398 -0.42 0.01905" />
    <axis xyz="1 0 0"/>
  </joint>

  <!-- .......................................................................................... -->
  <!-- helps to see the wheel rotation -->
  <link name="left_wheel_rear_stripe">
    <visual>
      <geometry>
        <box size="0.01 0.01 0.08"/>
      </geometry>
      <origin xyz="-0.01 0 0" />
      <material name="blue"/>
    </visual> 

    <!-- Just visual aid. Has no mass -->
    <inertial>
      <mass value="0" />
      <inertia ixx="0" ixy="0.0" ixz="0.0" iyy="0" iyz="0.0" izz="0"/>
    </inertial>
  </link>
  <joint name="left_wheel_rear_to_stripe" type="fixed">
    <parent link="left_wheel_rear"/>
    <child link="left_wheel_rear_stripe"/>
  </joint>

</robot>